<?xml version="1.0" encoding="UTF-8"?>
<testsuite name="Test"
           tests="1"
           failures="1"
           errors="0"
           skipped="0"
           time="1.045">
  <properties />
            <testcase name="goodsSaveTest" time="1.045" classname="Testcase.APIgoodsSaveTest">
                <failure type="java.lang.AssertionError"
                  message="+++ expected [true] but found [false]"
              >
<![CDATA[java.lang.AssertionError: +++ expected [true] but found [false]
  org.testng.Assert.fail(Assert.java:94)
  org.testng.Assert.failNotEquals(Assert.java:494)
  org.testng.Assert.assertTrue(Assert.java:42)
  Testcase.APIgoodsSaveTest.goodsSaveTest(APIgoodsSaveTest.java:28)
  sun.reflect.NativeMethodAccessorImpl.invoke0(Native Method)
  sun.reflect.NativeMethodAccessorImpl.invoke(Unknown Source)
  sun.reflect.DelegatingMethodAccessorImpl.invoke(Unknown Source)
  java.lang.reflect.Method.invoke(Unknown Source)
  org.testng.internal.MethodInvocationHelper.invokeMethod(MethodInvocationHelper.java:84)
  org.testng.internal.Invoker.invokeMethod(Invoker.java:714)
  org.testng.internal.Invoker.retryFailed(Invoker.java:1049)
  org.testng.internal.Invoker.invokeTestMethods(Invoker.java:1254)
  org.testng.internal.TestMethodWorker.invokeTestMethods(TestMethodWorker.java:127)
  org.testng.internal.TestMethodWorker.run(TestMethodWorker.java:111)
  java.util.concurrent.ThreadPoolExecutor.runWorker(Unknown Source)
  java.util.concurrent.ThreadPoolExecutor$Worker.run(Unknown Source)
  java.lang.Thread.run(Unknown Source)
]]>
      </failure>

          </testcase>
  
  
  
</testsuite>
